{
 "cells": [
  {
   "cell_type": "code",
   "execution_count": null,
   "id": "c91f0a8d",
   "metadata": {},
   "outputs": [],
   "source": [
    "%run gui.py"
   ]
  },
  {
   "cell_type": "code",
   "execution_count": null,
   "id": "3c3250c4",
   "metadata": {},
   "outputs": [],
   "source": [
    "%run G-UI.py"
   ]
  },
  {
   "cell_type": "code",
   "execution_count": 5,
   "id": "077aa183",
   "metadata": {},
   "outputs": [
    {
     "ename": "UnimplementedError",
     "evalue": "Graph execution error:\n\nDetected at node sequential_2/Cast defined at (most recent call last):\n  File \"<frozen runpy>\", line 198, in _run_module_as_main\n\n  File \"<frozen runpy>\", line 88, in _run_code\n\n  File \"C:\\Users\\RGUKT\\AppData\\Roaming\\Python\\Python311\\site-packages\\ipykernel_launcher.py\", line 17, in <module>\n\n  File \"C:\\Users\\RGUKT\\AppData\\Roaming\\Python\\Python311\\site-packages\\traitlets\\config\\application.py\", line 1043, in launch_instance\n\n  File \"C:\\Users\\RGUKT\\AppData\\Roaming\\Python\\Python311\\site-packages\\ipykernel\\kernelapp.py\", line 736, in start\n\n  File \"C:\\Users\\RGUKT\\AppData\\Roaming\\Python\\Python311\\site-packages\\tornado\\platform\\asyncio.py\", line 195, in start\n\n  File \"C:\\Users\\RGUKT\\anaconda2\\Lib\\asyncio\\base_events.py\", line 607, in run_forever\n\n  File \"C:\\Users\\RGUKT\\anaconda2\\Lib\\asyncio\\base_events.py\", line 1922, in _run_once\n\n  File \"C:\\Users\\RGUKT\\anaconda2\\Lib\\asyncio\\events.py\", line 80, in _run\n\n  File \"C:\\Users\\RGUKT\\AppData\\Roaming\\Python\\Python311\\site-packages\\ipykernel\\kernelbase.py\", line 516, in dispatch_queue\n\n  File \"C:\\Users\\RGUKT\\AppData\\Roaming\\Python\\Python311\\site-packages\\ipykernel\\kernelbase.py\", line 505, in process_one\n\n  File \"C:\\Users\\RGUKT\\AppData\\Roaming\\Python\\Python311\\site-packages\\ipykernel\\kernelbase.py\", line 412, in dispatch_shell\n\n  File \"C:\\Users\\RGUKT\\AppData\\Roaming\\Python\\Python311\\site-packages\\ipykernel\\kernelbase.py\", line 740, in execute_request\n\n  File \"C:\\Users\\RGUKT\\AppData\\Roaming\\Python\\Python311\\site-packages\\ipykernel\\ipkernel.py\", line 422, in do_execute\n\n  File \"C:\\Users\\RGUKT\\AppData\\Roaming\\Python\\Python311\\site-packages\\ipykernel\\zmqshell.py\", line 546, in run_cell\n\n  File \"C:\\Users\\RGUKT\\AppData\\Roaming\\Python\\Python311\\site-packages\\IPython\\core\\interactiveshell.py\", line 3009, in run_cell\n\n  File \"C:\\Users\\RGUKT\\AppData\\Roaming\\Python\\Python311\\site-packages\\IPython\\core\\interactiveshell.py\", line 3064, in _run_cell\n\n  File \"C:\\Users\\RGUKT\\AppData\\Roaming\\Python\\Python311\\site-packages\\IPython\\core\\async_helpers.py\", line 129, in _pseudo_sync_runner\n\n  File \"C:\\Users\\RGUKT\\AppData\\Roaming\\Python\\Python311\\site-packages\\IPython\\core\\interactiveshell.py\", line 3269, in run_cell_async\n\n  File \"C:\\Users\\RGUKT\\AppData\\Roaming\\Python\\Python311\\site-packages\\IPython\\core\\interactiveshell.py\", line 3448, in run_ast_nodes\n\n  File \"C:\\Users\\RGUKT\\AppData\\Roaming\\Python\\Python311\\site-packages\\IPython\\core\\interactiveshell.py\", line 3508, in run_code\n\n  File \"C:\\Users\\RGUKT\\AppData\\Local\\Temp\\ipykernel_3376\\142431827.py\", line 1, in <module>\n\n  File \"C:\\Users\\RGUKT\\AppData\\Roaming\\Python\\Python311\\site-packages\\IPython\\core\\interactiveshell.py\", line 2417, in run_line_magic\n\n  File \"C:\\Users\\RGUKT\\AppData\\Roaming\\Python\\Python311\\site-packages\\IPython\\core\\magics\\execution.py\", line 834, in run\n\n  File \"C:\\Users\\RGUKT\\AppData\\Roaming\\Python\\Python311\\site-packages\\IPython\\core\\magics\\execution.py\", line 819, in run\n\n  File \"C:\\Users\\RGUKT\\AppData\\Roaming\\Python\\Python311\\site-packages\\IPython\\core\\interactiveshell.py\", line 2866, in safe_execfile\n\n  File \"C:\\Users\\RGUKT\\AppData\\Roaming\\Python\\Python311\\site-packages\\IPython\\utils\\py3compat.py\", line 55, in execfile\n\n  File \"C:\\Users\\RGUKT\\Documents\\NULL CLASS project\\Translation_app\\problem.py\", line 26, in <module>\n\n  File \"C:\\Users\\RGUKT\\anaconda2\\Lib\\site-packages\\keras\\src\\utils\\traceback_utils.py\", line 65, in error_handler\n\n  File \"C:\\Users\\RGUKT\\anaconda2\\Lib\\site-packages\\keras\\src\\engine\\training.py\", line 2655, in predict\n\n  File \"C:\\Users\\RGUKT\\anaconda2\\Lib\\site-packages\\keras\\src\\engine\\training.py\", line 2440, in predict_function\n\n  File \"C:\\Users\\RGUKT\\anaconda2\\Lib\\site-packages\\keras\\src\\engine\\training.py\", line 2425, in step_function\n\n  File \"C:\\Users\\RGUKT\\anaconda2\\Lib\\site-packages\\keras\\src\\engine\\training.py\", line 2413, in run_step\n\n  File \"C:\\Users\\RGUKT\\anaconda2\\Lib\\site-packages\\keras\\src\\engine\\training.py\", line 2381, in predict_step\n\n  File \"C:\\Users\\RGUKT\\anaconda2\\Lib\\site-packages\\keras\\src\\utils\\traceback_utils.py\", line 65, in error_handler\n\n  File \"C:\\Users\\RGUKT\\anaconda2\\Lib\\site-packages\\keras\\src\\engine\\training.py\", line 590, in __call__\n\n  File \"C:\\Users\\RGUKT\\anaconda2\\Lib\\site-packages\\keras\\src\\utils\\traceback_utils.py\", line 65, in error_handler\n\n  File \"C:\\Users\\RGUKT\\anaconda2\\Lib\\site-packages\\keras\\src\\engine\\base_layer.py\", line 1149, in __call__\n\n  File \"C:\\Users\\RGUKT\\anaconda2\\Lib\\site-packages\\keras\\src\\utils\\traceback_utils.py\", line 96, in error_handler\n\n  File \"C:\\Users\\RGUKT\\anaconda2\\Lib\\site-packages\\keras\\src\\engine\\sequential.py\", line 398, in call\n\n  File \"C:\\Users\\RGUKT\\anaconda2\\Lib\\site-packages\\keras\\src\\engine\\functional.py\", line 515, in call\n\n  File \"C:\\Users\\RGUKT\\anaconda2\\Lib\\site-packages\\keras\\src\\engine\\functional.py\", line 654, in _run_internal_graph\n\n  File \"C:\\Users\\RGUKT\\anaconda2\\Lib\\site-packages\\keras\\src\\engine\\functional.py\", line 751, in _conform_to_reference_input\n\nCast string to float is not supported\n\t [[{{node sequential_2/Cast}}]] [Op:__inference_predict_function_63824]",
     "output_type": "error",
     "traceback": [
      "\u001b[1;31m---------------------------------------------------------------------------\u001b[0m",
      "\u001b[1;31mUnimplementedError\u001b[0m                        Traceback (most recent call last)",
      "File \u001b[1;32m~\\Documents\\NULL CLASS project\\Translation_app\\problem.py:26\u001b[0m\n\u001b[0;32m     23\u001b[0m input_sequence \u001b[38;5;241m=\u001b[39m np\u001b[38;5;241m.\u001b[39marray([[start_token]])\n\u001b[0;32m     25\u001b[0m \u001b[38;5;66;03m# Predict the next word probabilities\u001b[39;00m\n\u001b[1;32m---> 26\u001b[0m prediction \u001b[38;5;241m=\u001b[39m \u001b[43mmodel\u001b[49m\u001b[38;5;241;43m.\u001b[39;49m\u001b[43mpredict\u001b[49m\u001b[43m(\u001b[49m\u001b[43minput_sequence\u001b[49m\u001b[43m)\u001b[49m\n\u001b[0;32m     27\u001b[0m predicted_word_index \u001b[38;5;241m=\u001b[39m np\u001b[38;5;241m.\u001b[39margmax(prediction[\u001b[38;5;241m0\u001b[39m])\n\u001b[0;32m     29\u001b[0m \u001b[38;5;66;03m# Get the predicted word based on the index\u001b[39;00m\n",
      "File \u001b[1;32m~\\anaconda2\\Lib\\site-packages\\keras\\src\\utils\\traceback_utils.py:70\u001b[0m, in \u001b[0;36mfilter_traceback.<locals>.error_handler\u001b[1;34m(*args, **kwargs)\u001b[0m\n\u001b[0;32m     67\u001b[0m     filtered_tb \u001b[38;5;241m=\u001b[39m _process_traceback_frames(e\u001b[38;5;241m.\u001b[39m__traceback__)\n\u001b[0;32m     68\u001b[0m     \u001b[38;5;66;03m# To get the full stack trace, call:\u001b[39;00m\n\u001b[0;32m     69\u001b[0m     \u001b[38;5;66;03m# `tf.debugging.disable_traceback_filtering()`\u001b[39;00m\n\u001b[1;32m---> 70\u001b[0m     \u001b[38;5;28;01mraise\u001b[39;00m e\u001b[38;5;241m.\u001b[39mwith_traceback(filtered_tb) \u001b[38;5;28;01mfrom\u001b[39;00m \u001b[38;5;28;01mNone\u001b[39;00m\n\u001b[0;32m     71\u001b[0m \u001b[38;5;28;01mfinally\u001b[39;00m:\n\u001b[0;32m     72\u001b[0m     \u001b[38;5;28;01mdel\u001b[39;00m filtered_tb\n",
      "File \u001b[1;32m~\\anaconda2\\Lib\\site-packages\\tensorflow\\python\\eager\\execute.py:53\u001b[0m, in \u001b[0;36mquick_execute\u001b[1;34m(op_name, num_outputs, inputs, attrs, ctx, name)\u001b[0m\n\u001b[0;32m     51\u001b[0m \u001b[38;5;28;01mtry\u001b[39;00m:\n\u001b[0;32m     52\u001b[0m   ctx\u001b[38;5;241m.\u001b[39mensure_initialized()\n\u001b[1;32m---> 53\u001b[0m   tensors \u001b[38;5;241m=\u001b[39m pywrap_tfe\u001b[38;5;241m.\u001b[39mTFE_Py_Execute(ctx\u001b[38;5;241m.\u001b[39m_handle, device_name, op_name,\n\u001b[0;32m     54\u001b[0m                                       inputs, attrs, num_outputs)\n\u001b[0;32m     55\u001b[0m \u001b[38;5;28;01mexcept\u001b[39;00m core\u001b[38;5;241m.\u001b[39m_NotOkStatusException \u001b[38;5;28;01mas\u001b[39;00m e:\n\u001b[0;32m     56\u001b[0m   \u001b[38;5;28;01mif\u001b[39;00m name \u001b[38;5;129;01mis\u001b[39;00m \u001b[38;5;129;01mnot\u001b[39;00m \u001b[38;5;28;01mNone\u001b[39;00m:\n",
      "\u001b[1;31mUnimplementedError\u001b[0m: Graph execution error:\n\nDetected at node sequential_2/Cast defined at (most recent call last):\n  File \"<frozen runpy>\", line 198, in _run_module_as_main\n\n  File \"<frozen runpy>\", line 88, in _run_code\n\n  File \"C:\\Users\\RGUKT\\AppData\\Roaming\\Python\\Python311\\site-packages\\ipykernel_launcher.py\", line 17, in <module>\n\n  File \"C:\\Users\\RGUKT\\AppData\\Roaming\\Python\\Python311\\site-packages\\traitlets\\config\\application.py\", line 1043, in launch_instance\n\n  File \"C:\\Users\\RGUKT\\AppData\\Roaming\\Python\\Python311\\site-packages\\ipykernel\\kernelapp.py\", line 736, in start\n\n  File \"C:\\Users\\RGUKT\\AppData\\Roaming\\Python\\Python311\\site-packages\\tornado\\platform\\asyncio.py\", line 195, in start\n\n  File \"C:\\Users\\RGUKT\\anaconda2\\Lib\\asyncio\\base_events.py\", line 607, in run_forever\n\n  File \"C:\\Users\\RGUKT\\anaconda2\\Lib\\asyncio\\base_events.py\", line 1922, in _run_once\n\n  File \"C:\\Users\\RGUKT\\anaconda2\\Lib\\asyncio\\events.py\", line 80, in _run\n\n  File \"C:\\Users\\RGUKT\\AppData\\Roaming\\Python\\Python311\\site-packages\\ipykernel\\kernelbase.py\", line 516, in dispatch_queue\n\n  File \"C:\\Users\\RGUKT\\AppData\\Roaming\\Python\\Python311\\site-packages\\ipykernel\\kernelbase.py\", line 505, in process_one\n\n  File \"C:\\Users\\RGUKT\\AppData\\Roaming\\Python\\Python311\\site-packages\\ipykernel\\kernelbase.py\", line 412, in dispatch_shell\n\n  File \"C:\\Users\\RGUKT\\AppData\\Roaming\\Python\\Python311\\site-packages\\ipykernel\\kernelbase.py\", line 740, in execute_request\n\n  File \"C:\\Users\\RGUKT\\AppData\\Roaming\\Python\\Python311\\site-packages\\ipykernel\\ipkernel.py\", line 422, in do_execute\n\n  File \"C:\\Users\\RGUKT\\AppData\\Roaming\\Python\\Python311\\site-packages\\ipykernel\\zmqshell.py\", line 546, in run_cell\n\n  File \"C:\\Users\\RGUKT\\AppData\\Roaming\\Python\\Python311\\site-packages\\IPython\\core\\interactiveshell.py\", line 3009, in run_cell\n\n  File \"C:\\Users\\RGUKT\\AppData\\Roaming\\Python\\Python311\\site-packages\\IPython\\core\\interactiveshell.py\", line 3064, in _run_cell\n\n  File \"C:\\Users\\RGUKT\\AppData\\Roaming\\Python\\Python311\\site-packages\\IPython\\core\\async_helpers.py\", line 129, in _pseudo_sync_runner\n\n  File \"C:\\Users\\RGUKT\\AppData\\Roaming\\Python\\Python311\\site-packages\\IPython\\core\\interactiveshell.py\", line 3269, in run_cell_async\n\n  File \"C:\\Users\\RGUKT\\AppData\\Roaming\\Python\\Python311\\site-packages\\IPython\\core\\interactiveshell.py\", line 3448, in run_ast_nodes\n\n  File \"C:\\Users\\RGUKT\\AppData\\Roaming\\Python\\Python311\\site-packages\\IPython\\core\\interactiveshell.py\", line 3508, in run_code\n\n  File \"C:\\Users\\RGUKT\\AppData\\Local\\Temp\\ipykernel_3376\\142431827.py\", line 1, in <module>\n\n  File \"C:\\Users\\RGUKT\\AppData\\Roaming\\Python\\Python311\\site-packages\\IPython\\core\\interactiveshell.py\", line 2417, in run_line_magic\n\n  File \"C:\\Users\\RGUKT\\AppData\\Roaming\\Python\\Python311\\site-packages\\IPython\\core\\magics\\execution.py\", line 834, in run\n\n  File \"C:\\Users\\RGUKT\\AppData\\Roaming\\Python\\Python311\\site-packages\\IPython\\core\\magics\\execution.py\", line 819, in run\n\n  File \"C:\\Users\\RGUKT\\AppData\\Roaming\\Python\\Python311\\site-packages\\IPython\\core\\interactiveshell.py\", line 2866, in safe_execfile\n\n  File \"C:\\Users\\RGUKT\\AppData\\Roaming\\Python\\Python311\\site-packages\\IPython\\utils\\py3compat.py\", line 55, in execfile\n\n  File \"C:\\Users\\RGUKT\\Documents\\NULL CLASS project\\Translation_app\\problem.py\", line 26, in <module>\n\n  File \"C:\\Users\\RGUKT\\anaconda2\\Lib\\site-packages\\keras\\src\\utils\\traceback_utils.py\", line 65, in error_handler\n\n  File \"C:\\Users\\RGUKT\\anaconda2\\Lib\\site-packages\\keras\\src\\engine\\training.py\", line 2655, in predict\n\n  File \"C:\\Users\\RGUKT\\anaconda2\\Lib\\site-packages\\keras\\src\\engine\\training.py\", line 2440, in predict_function\n\n  File \"C:\\Users\\RGUKT\\anaconda2\\Lib\\site-packages\\keras\\src\\engine\\training.py\", line 2425, in step_function\n\n  File \"C:\\Users\\RGUKT\\anaconda2\\Lib\\site-packages\\keras\\src\\engine\\training.py\", line 2413, in run_step\n\n  File \"C:\\Users\\RGUKT\\anaconda2\\Lib\\site-packages\\keras\\src\\engine\\training.py\", line 2381, in predict_step\n\n  File \"C:\\Users\\RGUKT\\anaconda2\\Lib\\site-packages\\keras\\src\\utils\\traceback_utils.py\", line 65, in error_handler\n\n  File \"C:\\Users\\RGUKT\\anaconda2\\Lib\\site-packages\\keras\\src\\engine\\training.py\", line 590, in __call__\n\n  File \"C:\\Users\\RGUKT\\anaconda2\\Lib\\site-packages\\keras\\src\\utils\\traceback_utils.py\", line 65, in error_handler\n\n  File \"C:\\Users\\RGUKT\\anaconda2\\Lib\\site-packages\\keras\\src\\engine\\base_layer.py\", line 1149, in __call__\n\n  File \"C:\\Users\\RGUKT\\anaconda2\\Lib\\site-packages\\keras\\src\\utils\\traceback_utils.py\", line 96, in error_handler\n\n  File \"C:\\Users\\RGUKT\\anaconda2\\Lib\\site-packages\\keras\\src\\engine\\sequential.py\", line 398, in call\n\n  File \"C:\\Users\\RGUKT\\anaconda2\\Lib\\site-packages\\keras\\src\\engine\\functional.py\", line 515, in call\n\n  File \"C:\\Users\\RGUKT\\anaconda2\\Lib\\site-packages\\keras\\src\\engine\\functional.py\", line 654, in _run_internal_graph\n\n  File \"C:\\Users\\RGUKT\\anaconda2\\Lib\\site-packages\\keras\\src\\engine\\functional.py\", line 751, in _conform_to_reference_input\n\nCast string to float is not supported\n\t [[{{node sequential_2/Cast}}]] [Op:__inference_predict_function_63824]"
     ]
    }
   ],
   "source": [
    "%run problem.py"
   ]
  }
 ],
 "metadata": {
  "kernelspec": {
   "display_name": "Python 3 (ipykernel)",
   "language": "python",
   "name": "python3"
  },
  "language_info": {
   "codemirror_mode": {
    "name": "ipython",
    "version": 3
   },
   "file_extension": ".py",
   "mimetype": "text/x-python",
   "name": "python",
   "nbconvert_exporter": "python",
   "pygments_lexer": "ipython3",
   "version": "3.11.4"
  }
 },
 "nbformat": 4,
 "nbformat_minor": 5
}
